<?xml version="1.0"?>
<robot xmlns:xacro="http://www.ros.org/wiki/xacro" >

    <xacro:include filename="$(find servo_hardware)/urdf/inertial_macros.xacro" />
    <xacro:include filename="$(find servo_hardware)/urdf/servo.materials.xacro" />

    <link name="base_link" />
    <joint name="fixation" type="fixed">
        <parent link="base_link"/>
        <child link="motor"/>
        <origin xyz="0 0 0.267"/>
    </joint>

    <!-- Dimension here: 

    https://yorobotics.co/producto/sg90s-servomotor-microservo-miniservo-sg90-domicilio-arduin
    
     -->

    <!-- MOTOR LINK -->

    <link name="motor">
        <visual>
            <origin xyz="0.0 0.0535 -0.1535"/>
            <geometry>
                <box size="0.118 0.225 0.227"/>
            </geometry>
            <material name="blue"/>
        </visual>
        <visual>
            <origin xyz="0.0 0.0 -0.025"/>
            <geometry>
                <cylinder radius="0.059" length="0.05"/>
            </geometry>
        </visual>
        <visual>
            <origin xyz="0.0 0.063 -0.025"/>
            <geometry>
                <cylinder radius="0.025" length="0.05"/>
            </geometry>
        </visual>
        <visual>
            <origin xyz="0.0 0.0535 -0.0955"/>
            <geometry>
                <box size="0.118 0.319 0.025"/>
            </geometry>
        </visual>
        <collision>
            <origin xyz="0.0 0.0535 -0.1335"/>
            <geometry>
                <box size="0.118 0.319 0.267"/>
            </geometry>
        </collision>
        <xacro:inertial_box mass="0.15" x="0.118" y="0.319" z="0.267">
            <origin xyz="0.0 0.0535 -0.1335" rpy="0 0 0"/>
        </xacro:inertial_box>
    </link>

    <!-- ARM LINK -->

    <joint name="servo_joint" type="revolute">
        <limit lower="-${pi/2}" upper="${pi/2}" effort="0.0" velocity="0.0"/>
        <parent link="motor"/>
        <child link="arm"/>
        <origin xyz="0 0 0.042" rpy="0 0 0" />
        <axis xyz="0 0 1"/>
    </joint>

    <link name="arm">
        <visual>
            <origin xyz="0.0 0.0 -0.027"/>
            <geometry>
                <cylinder radius="0.023" length="0.03"/>
            </geometry>
            <material name="white"/>
        </visual>
        <visual>
            <origin xyz="0.0 0.0 -0.021"/>
            <geometry>
                <cylinder radius="0.05" length="0.054"/>
            </geometry>
        </visual>
        <visual>
            <origin xyz="0.127 0.0 -0.01"/>
            <geometry>
                <box size="0.254 0.08 0.02"/>
            </geometry>
        </visual>
        <collision>
            <origin xyz="0.127 0.0 -0.01"/>
            <geometry>
                 <box size="0.304 0.08 0.02"/>
            </geometry>
        </collision>
        <xacro:inertial_cylinder mass="0.023" radius="0.05" length="0.03">
            <origin xyz="0 0 0" rpy="0 0 0"/>
        </xacro:inertial_cylinder>
    </link>

</robot>